<?xml version="1.0" ?>
<robot name="2FG7_outwards" xmlns:xacro="http://www.ros.org/wiki/xacro">

<xacro:include filename="$(find 2FG7_outwards_description)/urdf/materials.xacro" />
<xacro:include filename="$(find 2FG7_outwards_description)/urdf/2FG7_outwards.trans" />
<xacro:include filename="$(find 2FG7_outwards_description)/urdf/2FG7_outwards.gazebo" />
<link name="base_link">
  <inertial>
    <origin xyz="0.011012174829169254 0.029496925809376805 0.05531082379775077" rpy="0 0 0"/>
    <mass value="1.2646523179240974"/>
    <inertia ixx="0.001504" iyy="0.001812" izz="0.001053" ixy="-0.0" iyz="0.0" ixz="-3e-06"/>
  </inertial>
  <visual>
    <origin xyz="0 0 0" rpy="0 0 0"/>
    <geometry>
      <mesh filename="package://2FG7_outwards_description/meshes/base_link.stl" scale="0.001 0.001 0.001"/>
    </geometry>
    <material name="silver"/>
  </visual>
  <collision>
    <origin xyz="0 0 0" rpy="0 0 0"/>
    <geometry>
      <mesh filename="package://2FG7_outwards_description/meshes/base_link.stl" scale="0.001 0.001 0.001"/>
    </geometry>
  </collision>
</link>

<link name="right_finger_v1_1">
  <inertial>
    <origin xyz="0.006813460666601066 -2.8812403068227688e-06 0.0280342154862306" rpy="0 0 0"/>
    <mass value="0.023219383355922288"/>
    <inertia ixx="6e-06" iyy="5e-06" izz="2e-06" ixy="-0.0" iyz="-0.0" ixz="1e-06"/>
  </inertial>
  <visual>
    <origin xyz="0.032239 -0.029494 -0.09445" rpy="0 0 0"/>
    <geometry>
      <mesh filename="package://2FG7_outwards_description/meshes/right_finger_v1_1.stl" scale="0.001 0.001 0.001"/>
    </geometry>
    <material name="silver"/>
  </visual>
  <collision>
    <origin xyz="0.032239 -0.029494 -0.09445" rpy="0 0 0"/>
    <geometry>
      <mesh filename="package://2FG7_outwards_description/meshes/right_finger_v1_1.stl" scale="0.001 0.001 0.001"/>
    </geometry>
  </collision>
</link>

<link name="left_finger_v1_1">
  <inertial>
    <origin xyz="-0.006813132689127449 3.0377198543818373e-06 0.028034215486240202" rpy="0 0 0"/>
    <mass value="0.023219383355922288"/>
    <inertia ixx="6e-06" iyy="5e-06" izz="2e-06" ixy="-0.0" iyz="0.0" ixz="-1e-06"/>
  </inertial>
  <visual>
    <origin xyz="-0.054361 -0.029494 -0.09445" rpy="0 0 0"/>
    <geometry>
      <mesh filename="package://2FG7_outwards_description/meshes/left_finger_v1_1.stl" scale="0.001 0.001 0.001"/>
    </geometry>
    <material name="silver"/>
  </visual>
  <collision>
    <origin xyz="-0.054361 -0.029494 -0.09445" rpy="0 0 0"/>
    <geometry>
      <mesh filename="package://2FG7_outwards_description/meshes/left_finger_v1_1.stl" scale="0.001 0.001 0.001"/>
    </geometry>
  </collision>
</link>

<joint name="right_finger_joint" type="fixed">
  <origin xyz="-0.032239 0.029494 0.09445" rpy="0 0 0"/>
  <parent link="base_link"/>
  <child link="right_finger_v1_1"/>
</joint>

<joint name="lef_finger_joint" type="prismatic">
  <origin xyz="0.054361 0.029494 0.09445" rpy="0 0 0"/>
  <parent link="base_link"/>
  <child link="left_finger_v1_1"/>
  <axis xyz="-1.0 0.0 -0.0"/>
  <limit upper="0.038" lower="0.0" effort="100" velocity="100"/>
</joint>

</robot>
