<?xml version="1.0" ?>
<robot name="2FG7_v1" xmlns:xacro="http://www.ros.org/wiki/xacro">

<xacro:include filename="$(find 2FG7_v1_description)/urdf/materials.xacro" />
<xacro:include filename="$(find 2FG7_v1_description)/urdf/2FG7_v1.trans" />
<xacro:include filename="$(find 2FG7_v1_description)/urdf/2FG7_v1.gazebo" />
<link name="base_link">
  <inertial>
    <origin xyz="0.010178814540458351 0.029612115176374597 0.0036262445032836403" rpy="0 0 0"/>
    <mass value="0.15682933675903254"/>
    <inertia ixx="5.4e-05" iyy="7.3e-05" izz="0.000123" ixy="-0.0" iyz="-1e-06" ixz="1e-06"/>
  </inertial>
  <visual>
    <origin xyz="0 0 0" rpy="0 0 0"/>
    <geometry>
      <mesh filename="package://2FG7_v1_description/meshes/base_link.stl" scale="0.001 0.001 0.001"/>
    </geometry>
    <material name="silver"/>
  </visual>
  <collision>
    <origin xyz="0 0 0" rpy="0 0 0"/>
    <geometry>
      <mesh filename="package://2FG7_v1_description/meshes/base_link.stl" scale="0.001 0.001 0.001"/>
    </geometry>
  </collision>
</link>

<link name="core_1">
  <inertial>
    <origin xyz="-0.013300012185180721 0.01106097600275073 0.09080502945543174" rpy="0 0 0"/>
    <mass value="2.948825721698133"/>
    <inertia ixx="0.002459" iyy="0.003136" izz="0.002403" ixy="-0.0" iyz="-0.0" ixz="-0.0"/>
  </inertial>
  <visual>
    <origin xyz="-0.024361 -0.018433 0.029794" rpy="0 0 0"/>
    <geometry>
      <mesh filename="package://2FG7_v1_description/meshes/core_1.stl" scale="0.001 0.001 0.001"/>
    </geometry>
    <material name="silver"/>
  </visual>
  <collision>
    <origin xyz="-0.024361 -0.018433 0.029794" rpy="0 0 0"/>
    <geometry>
      <mesh filename="package://2FG7_v1_description/meshes/core_1.stl" scale="0.001 0.001 0.001"/>
    </geometry>
  </collision>
</link>

<link name="top_1">
  <inertial>
    <origin xyz="-0.0984998360112598 0.01106107823977395 0.03846822448871447" rpy="0 0 0"/>
    <mass value="0.5513523332843309"/>
    <inertia ixx="0.000164" iyy="0.000363" izz="0.00051" ixy="0.0" iyz="-0.0" ixz="-0.0"/>
  </inertial>
  <visual>
    <origin xyz="-0.109561 -0.018433 -0.069006" rpy="0 0 0"/>
    <geometry>
      <mesh filename="package://2FG7_v1_description/meshes/top_1.stl" scale="0.001 0.001 0.001"/>
    </geometry>
    <material name="silver"/>
  </visual>
  <collision>
    <origin xyz="-0.109561 -0.018433 -0.069006" rpy="0 0 0"/>
    <geometry>
      <mesh filename="package://2FG7_v1_description/meshes/top_1.stl" scale="0.001 0.001 0.001"/>
    </geometry>
  </collision>
</link>

<link name="right_finger_v1_1">
  <inertial>
    <origin xyz="-0.06137553933339885 0.1144471187596921 0.05392821548623168" rpy="0 0 0"/>
    <mass value="0.06750820716444073"/>
    <inertia ixx="1.8e-05" iyy="1.5e-05" izz="6e-06" ixy="-0.0" iyz="-0.0" ixz="3e-06"/>
  </inertial>
  <visual>
    <origin xyz="-0.0433 0.084956 -0.078556" rpy="0 0 0"/>
    <geometry>
      <mesh filename="package://2FG7_v1_description/meshes/right_finger_v1_1.stl" scale="0.001 0.001 0.001"/>
    </geometry>
    <material name="silver"/>
  </visual>
  <collision>
    <origin xyz="-0.0433 0.084956 -0.078556" rpy="0 0 0"/>
    <geometry>
      <mesh filename="package://2FG7_v1_description/meshes/right_finger_v1_1.stl" scale="0.001 0.001 0.001"/>
    </geometry>
  </collision>
</link>

<link name="left_finger_v1_1">
  <inertial>
    <origin xyz="0.08349786731087264 0.11445303771985518 0.05392821548623948" rpy="0 0 0"/>
    <mass value="0.06750820716444073"/>
    <inertia ixx="1.8e-05" iyy="1.5e-05" izz="6e-06" ixy="-0.0" iyz="0.0" ixz="-3e-06"/>
  </inertial>
  <visual>
    <origin xyz="0.0433 0.084956 -0.078556" rpy="0 0 0"/>
    <geometry>
      <mesh filename="package://2FG7_v1_description/meshes/left_finger_v1_1.stl" scale="0.001 0.001 0.001"/>
    </geometry>
    <material name="silver"/>
  </visual>
  <collision>
    <origin xyz="0.0433 0.084956 -0.078556" rpy="0 0 0"/>
    <geometry>
      <mesh filename="package://2FG7_v1_description/meshes/left_finger_v1_1.stl" scale="0.001 0.001 0.001"/>
    </geometry>
  </collision>
</link>

<joint name="base_link_to_core" type="fixed">
  <origin xyz="0.024361 0.018433 -0.029794" rpy="0 0 0"/>
  <parent link="base_link"/>
  <child link="core_1"/>
</joint>

<joint name="core_to_top" type="fixed">
  <origin xyz="0.0852 0.0 0.0988" rpy="0 0 0"/>
  <parent link="core_1"/>
  <child link="top_1"/>
</joint>

<joint name="top_to_right_finger" type="fixed">
  <origin xyz="-0.066261 -0.103389 0.00955" rpy="0 0 0"/>
  <parent link="top_1"/>
  <child link="right_finger_v1_1"/>
</joint>

<joint name="top_to_left_finger" type="prismatic">
  <origin xyz="-0.152861 -0.103389 0.00955" rpy="0 0 0"/>
  <parent link="top_1"/>
  <child link="left_finger_v1_1"/>
  <axis xyz="-1.0 0.0 -0.0"/>
  <limit upper="0.029" lower="0.0" effort="100" velocity="100"/>
</joint>

</robot>
