<?xml version="1.0" ?>
<robot name="2fg7_outwards" xmlns:xacro="http://www.ros.org/wiki/xacro">

<xacro:include filename="$(find onrobot_2fg7_description)/urdf/materials.xacro" />
<xacro:include filename="$(find onrobot_2fg7_description)/urdf/onrobot_2fg7.trans.xacro" />
<xacro:include filename="$(find onrobot_2fg7_description)/urdf/onrobot_2fg7.gazebo" />
<xacro:gripper_transmission/>
<xacro:gazebo_control is_control_on="false" />

<xacro:macro name="onrobot_2fg7_gripper" params="prefix finger_configuration=outwards">

  <xacro:property name="config" value="${finger_configuration}"/>
  <xacro:if value="${config == 'outwards'}">
    <link name="${prefix}base_link">
      <inertial>
        <origin xyz="-4.898915958379213e-05 2.84756960271082e-06 0.06811082379774974" rpy="0 0 0"/>
        <mass value="1.2646523179240972"/>
        <inertia ixx="0.001504" iyy="0.001812" izz="0.001053" ixy="-0.0" iyz="0.0" ixz="-3e-06"/>
      </inertial>
      <visual>
        <origin xyz="0 0 0" rpy="0 0 0"/>
        <geometry>
          <mesh filename="package://onrobot_2fg7_description/meshes/base_link.stl" scale="0.001 0.001 0.001"/>
        </geometry>
        <material name="silver"/>
      </visual>
      <collision>
        <origin xyz="0 0 0" rpy="0 0 0"/>
        <geometry>
          <mesh filename="package://onrobot_2fg7_description/meshes/base_link.stl" scale="0.001 0.001 0.001"/>
        </geometry>
      </collision>
    </link>

    <link name="${prefix}right_finger_link">
      <inertial>
        <origin xyz="0.017874296677847158 0.02949104051991925 0.01523421548622829" rpy="0 0 0"/>
        <mass value="0.023219383355922288"/>
        <inertia ixx="6e-06" iyy="5e-06" izz="2e-06" ixy="-0.0" iyz="-0.0" ixz="1e-06"/>
      </inertial>
      <visual>
        <origin xyz="0.054361 0.029494 -0.12005" rpy="0 0 0"/>
        <geometry>
          <mesh filename="package://onrobot_2fg7_description/meshes/right_finger_link.stl" scale="0.001 0.001 0.001"/>
        </geometry>
        <material name="silver"/>
      </visual>
      <collision name="right_finger_collision">
        <origin xyz="0.054361 0.029494 -0.12005" rpy="0 0 0"/>
        <geometry>
          <mesh filename="package://onrobot_2fg7_description/meshes/right_finger_link.stl" scale="0.001 0.001 0.001"/>
        </geometry>
      </collision>
    </link>

    <link name="${prefix}left_finger_link">
      <inertial>
        <origin xyz="0.004247703322119739 0.029496959480080673 0.015234215486237948" rpy="0 0 0"/>
        <mass value="0.023219383355922288"/>
        <inertia ixx="6e-06" iyy="5e-06" izz="2e-06" ixy="-0.0" iyz="0.0" ixz="-1e-06"/>
      </inertial>
      <visual>
        <origin xyz="-0.032239 0.029494 -0.12005" rpy="0 0 0"/>
        <geometry>
          <mesh filename="package://onrobot_2fg7_description/meshes/left_finger_link.stl" scale="0.001 0.001 0.001"/>
        </geometry>
        <material name="silver"/>
      </visual>
      <collision name="left_finger_collision">
        <origin xyz="-0.032239 0.029494 -0.12005" rpy="0 0 0"/>
        <geometry>
          <mesh filename="package://onrobot_2fg7_description/meshes/left_finger_link.stl" scale="0.001 0.001 0.001"/>
        </geometry>
      </collision>
    </link>

    <joint name="left_finger_joint" type="prismatic">
      <origin xyz="0.032239 -0.029494 0.12005" rpy="0 0 0"/>
      <parent link="${prefix}base_link"/>
      <child link="${prefix}left_finger_link"/>
      <axis xyz="-1.0 0.0 0.0"/>
      <limit lower="0.0" upper="0.019" effort="140" velocity="0.45"/> <!-- total 0.38 -->
    </joint>

    <joint name="right_finger_joint" type="prismatic">
      <origin xyz="-0.054361 -0.029494 0.12005" rpy="0 0 0"/>
      <parent link="${prefix}base_link"/>
      <child link="${prefix}right_finger_link"/>
      <axis xyz="1.0 0.0 0.0"/>
      <limit lower="-0.019" upper="0.019" effort="140" velocity="0.45"/>
      <mimic joint="left_finger_joint" multiplier="1.0"/>
    </joint>
  </xacro:if>

   <xacro:if value="${config == 'inwards'}">

    <link name="${prefix}base_link">
      <inertial>
        <origin xyz="-4.8989159583623376e-05 2.847569602502098e-06 0.06811082379775064" rpy="0 0 0"/>
        <mass value="1.2646523179240972"/>
        <inertia ixx="0.001504" iyy="0.001812" izz="0.001053" ixy="-0.0" iyz="0.0" ixz="-3e-06"/>
      </inertial>
      <visual>
        <origin xyz="0 0 0" rpy="0 0 0"/>
        <geometry>
          <mesh filename="package://onrobot_2fg7_description/meshes/base_link.stl" scale="0.001 0.001 0.001"/>
        </geometry>
        <material name="silver"/>
      </visual>
      <collision>
        <origin xyz="0 0 0" rpy="0 0 0"/>
        <geometry>
          <mesh filename="package://onrobot_2fg7_description/meshes/base_link.stl" scale="0.001 0.001 0.001"/>
        </geometry>
      </collision>
    </link>

    <link name="${prefix}right_finger_link">
      <inertial>
        <origin xyz="0.029847703322119633 0.029496959480087837 0.015234215486232036" rpy="0 0 0"/>
        <mass value="0.023219383355922288"/>
        <inertia ixx="6e-06" iyy="5e-06" izz="2e-06" ixy="-0.0" iyz="0.0" ixz="-1e-06"/>
      </inertial>
      <visual>
        <origin xyz="0.054361 0.029494 -0.12005" rpy="0 0 0"/>
        <geometry>
          <mesh filename="package://onrobot_2fg7_description/meshes/inwards/right_finger_link.stl" scale="0.001 0.001 0.001"/>
        </geometry>
        <material name="silver"/>
      </visual>
      <collision>
        <origin xyz="0.054361 0.029494 -0.12005" rpy="0 0 0"/>
        <geometry>
          <mesh filename="package://onrobot_2fg7_description/meshes/inwards/right_finger_link.stl" scale="0.001 0.001 0.001"/>
        </geometry>
      </collision>
    </link>

    <link name="${prefix}left_finger_link">
      <inertial>
        <origin xyz="-0.007725703322151688 0.029491040519911117 0.015234215486238503" rpy="0 0 0"/>
        <mass value="0.023219383355922288"/>
        <inertia ixx="6e-06" iyy="5e-06" izz="2e-06" ixy="-0.0" iyz="-0.0" ixz="1e-06"/>
      </inertial>
      <visual>
        <origin xyz="-0.032239 0.029494 -0.12005" rpy="0 0 0"/>
        <geometry>
          <mesh filename="package://onrobot_2fg7_description/meshes/inwards/left_finger_link.stl" scale="0.001 0.001 0.001"/>
        </geometry>
        <material name="silver"/>
      </visual>
      <collision>
        <origin xyz="-0.032239 0.029494 -0.12005" rpy="0 0 0"/>
        <geometry>
          <mesh filename="package://onrobot_2fg7_description/meshes/inwards/left_finger_link.stl" scale="0.001 0.001 0.001"/>
        </geometry>
      </collision>
    </link>



    <joint name="left_finger_joint" type="prismatic">
      <origin xyz="0.032239 -0.029494 0.12005" rpy="0 0 0"/>
      <parent link="${prefix}base_link"/>
      <child link="${prefix}left_finger_link"/>
      <axis xyz="-1.0 0.0 0.0"/>
      <limit upper="0.0" lower="0.019" effort="100" velocity="0.45"/>
    </joint>
    
    <joint name="right_finger_joint" type="prismatic">
      <origin xyz="-0.054361 -0.029494 0.12005" rpy="0 0 0"/>
      <parent link="${prefix}base_link"/>
      <child link="${prefix}right_finger_link"/>
      <axis xyz="1.0 0.0 0.0"/>
      <limit lower="-0.019" upper="0.019" effort="100" velocity="0.45"/>
      <mimic joint="left_finger_joint" multiplier="1.0"/>
    </joint>

   </xacro:if>
 </xacro:macro>


</robot>
