<?xml version="1.0" ?>
<robot name="2FG7_inwards" xmlns:xacro="http://www.ros.org/wiki/xacro">

<xacro:include filename="$(find 2FG7_inwards_description)/urdf/materials.xacro" />
<xacro:include filename="$(find 2FG7_inwards_description)/urdf/2FG7_inwards.trans" />
<xacro:include filename="$(find 2FG7_inwards_description)/urdf/2FG7_inwards.gazebo" />
<link name="base_link">
  <inertial>
    <origin xyz="-4.8989159583623376e-05 2.847569602502098e-06 0.06811082379775064" rpy="0 0 0"/>
    <mass value="1.2646523179240972"/>
    <inertia ixx="0.001504" iyy="0.001812" izz="0.001053" ixy="-0.0" iyz="0.0" ixz="-3e-06"/>
  </inertial>
  <visual>
    <origin xyz="0 0 0" rpy="0 0 0"/>
    <geometry>
      <mesh filename="package://2FG7_inwards_description/meshes/base_link.stl" scale="0.001 0.001 0.001"/>
    </geometry>
    <material name="silver"/>
  </visual>
  <collision>
    <origin xyz="0 0 0" rpy="0 0 0"/>
    <geometry>
      <mesh filename="package://2FG7_inwards_description/meshes/base_link.stl" scale="0.001 0.001 0.001"/>
    </geometry>
  </collision>
</link>

<link name="right_finger_v1_1">
  <inertial>
    <origin xyz="0.029847703322119633 0.029496959480087837 0.015234215486232036" rpy="0 0 0"/>
    <mass value="0.023219383355922288"/>
    <inertia ixx="6e-06" iyy="5e-06" izz="2e-06" ixy="-0.0" iyz="0.0" ixz="-1e-06"/>
  </inertial>
  <visual>
    <origin xyz="0.054361 0.029494 -0.12005" rpy="0 0 0"/>
    <geometry>
      <mesh filename="package://2FG7_inwards_description/meshes/right_finger_v1_1.stl" scale="0.001 0.001 0.001"/>
    </geometry>
    <material name="silver"/>
  </visual>
  <collision>
    <origin xyz="0.054361 0.029494 -0.12005" rpy="0 0 0"/>
    <geometry>
      <mesh filename="package://2FG7_inwards_description/meshes/right_finger_v1_1.stl" scale="0.001 0.001 0.001"/>
    </geometry>
  </collision>
</link>

<link name="left_finger_v1_1">
  <inertial>
    <origin xyz="-0.007725703322151688 0.029491040519911117 0.015234215486238503" rpy="0 0 0"/>
    <mass value="0.023219383355922288"/>
    <inertia ixx="6e-06" iyy="5e-06" izz="2e-06" ixy="-0.0" iyz="-0.0" ixz="1e-06"/>
  </inertial>
  <visual>
    <origin xyz="-0.032239 0.029494 -0.12005" rpy="0 0 0"/>
    <geometry>
      <mesh filename="package://2FG7_inwards_description/meshes/left_finger_v1_1.stl" scale="0.001 0.001 0.001"/>
    </geometry>
    <material name="silver"/>
  </visual>
  <collision>
    <origin xyz="-0.032239 0.029494 -0.12005" rpy="0 0 0"/>
    <geometry>
      <mesh filename="package://2FG7_inwards_description/meshes/left_finger_v1_1.stl" scale="0.001 0.001 0.001"/>
    </geometry>
  </collision>
</link>

<joint name="right_finger_joint" type="fixed">
  <origin xyz="-0.054361 -0.029494 0.12005" rpy="0 0 0"/>
  <parent link="base_link"/>
  <child link="right_finger_v1_1"/>
</joint>

<joint name="lef_finger_joint" type="prismatic">
  <origin xyz="0.032239 -0.029494 0.12005" rpy="0 0 0"/>
  <parent link="base_link"/>
  <child link="left_finger_v1_1"/>
  <axis xyz="-1.0 0.0 -0.0"/>
  <limit upper="0.038" lower="0.0" effort="100" velocity="100"/>
</joint>

</robot>
